Workbook

Sheet Orders
A1: Region | B1: State | C1: City | D1: Account | E1: Order ID | F1: Order Date | G1: Ship Date | H1: Days to Ship | I1: Sales Rep | J1: Channel | K1: Category | L1: Product | M1: SKU | N1: Qty | O1: Unit Price | P1: Extended | Q1: Discount % | R1: Discount Amt | S1: Net | T1: Sales Tax | U1: Total | V1: Shipping | W1: Landed Total | X1: Status | Y1: Notes
A2: Midwest | B2: Kentucky | C2: Louisville | D2: Ridge Distributors | E2: 41000 | F2: 46232 | G2: 46238 | H2: =IF(G2="","",G2-F2) -> 6 | I2: M. Okafor | J2: Online | K2: Hand Tools | L2: Torpedo Level 9 in | M2: HT-0900 | N2: 50 | O2: 14.25 | P2: =N2*O2 -> 712.5 | Q2: 0 | R2: =ROUND(P2*Q2,2) -> 0 | S2: =P2-R2 -> 712.5 | T2: =ROUND(S2*Assumptions!$B$2,2) -> 42.75 | U2: =S2+T2 -> 755.25 | V2: 6.12 | W2: =U2+V2 -> 761.37 | X2: Shipped
A3: Midwest | B3: Kentucky | C3: Louisville | D3: Ridge Distributors | E3: 41004 | F3: 46174 | H3: =IF(G3="","",G3-F3) | I3: M. Okafor | J3: Distributor | K3: Safety | L3: Safety Glasses, Clear (12) | M3: SF-0012 | N3: 50 | O3: 27.6 | P3: =N3*O3 -> 1380 | Q3: 0.1 | R3: =ROUND(P3*Q3,2) -> 138 | S3: =P3-R3 -> 1242 | T3: =ROUND(S3*Assumptions!$B$2,2) -> 74.52 | U3: =S3+T3 -> 1316.52 | V3: 27.9 | W3: =U3+V3 -> 1344.42 | X3: Backordered
A4: Midwest | B4: Kentucky | C4: Louisville | D4: Granite Fabrication | E4: 41008 | F4: 46029 | G4: 46030 | H4: =IF(G4="","",G4-F4) -> 1 | I4: A. Reyes | J4: Direct | K4: Electrical | L4: Duplex Outlet 15A (10) | M4: EL-1510 | N4: 10 | O4: 13.4 | P4: =N4*O4 -> 134 | Q4: 0.15 | R4: =ROUND(P4*Q4,2) -> 20.1 | S4: =P4-R4 -> 113.9 | T4: =ROUND(S4*Assumptions!$B$2,2) -> 6.83 | U4: =S4+T4 -> 120.73 | V4: 25.42 | W4: =U4+V4 -> 146.15 | X4: Delivered | Y4: Damaged in transit; replaced
A5: Midwest | B5: Kentucky | C5: Louisville | D5: Granite Fabrication | E5: 41011 | F5: 46077 | H5: =IF(G5="","",G5-F5) | I5: M. Okafor | J5: Online | K5: Fasteners | L5: Deck Screw #10 x 3 (5 lb) | M5: FAS-1003 | N5: 50 | O5: 31.9 | P5: =N5*O5 -> 1595 | Q5: 0 | R5: =ROUND(P5*Q5,2) -> 0 | S5: =P5-R5 -> 1595 | T5: =ROUND(S5*Assumptions!$B$2,2) -> 95.7 | U5: =S5+T5 -> 1690.7 | V5: 0 | W5: =U5+V5 -> 1690.7 | X5: Open | Y5: New account
A6: Midwest | B6: Kentucky | C6: Louisville | D6: Granite Fabrication | E6: 41013 | F6: 46257 | G6: 46262 | H6: =IF(G6="","",G6-F6) -> 5 | I6: M. Okafor | J6: Distributor | K6: Fasteners | L6: Deck Screw #10 x 3 (5 lb) | M6: FAS-1003 | N6: 10 | O6: 31.9 | P6: =N6*O6 -> 319 | Q6: 0 | R6: =ROUND(P6*Q6,2) -> 0 | S6: =P6-R6 -> 319 | T6: =ROUND(S6*Assumptions!$B$2,2) -> 19.14 | U6: =S6+T6 -> 338.14 | V6: 38.82 | W6: =U6+V6 -> 376.96 | X6: Delivered
A7: Midwest | B7: Kentucky | C7: Louisville | D7: Anchor Outfitters | E7: 41019 | F7: 46045 | G7: 46049 | H7: =IF(G7="","",G7-F7) -> 4 | I7: M. Okafor | J7: Online | K7: Fasteners | L7: Lag Screw 3/8 x 4 (50) | M7: FAS-3804 | N7: 6 | O7: 22.75 | P7: =N7*O7 -> 136.5 | Q7: 0.05 | R7: =ROUND(P7*Q7,2) -> 6.83 | S7: =P7-R7 -> 129.67 | T7: =ROUND(S7*Assumptions!$B$2,2) -> 7.78 | U7: =S7+T7 -> 137.45 | V7: 1 | W7: =U7+V7 -> 138.45 | X7: Delivered | Y7: New account
A8: Midwest | B8: Kentucky | C8: Louisville | D8: Anchor Outfitters | E8: 41023 | F8: 46140 | G8: 46149 | H8: =IF(G8="","",G8-F8) -> 9 | I8: A. Reyes | J8: Direct | K8: Electrical | L8: LED Shop Light 4 ft | M8: EL-0400 | N8: 15 | O8: 42 | P8: =N8*O8 -> 630 | Q8: 0 | R8: =ROUND(P8*Q8,2) -> 0 | S8: =P8-R8 -> 630 | T8: =ROUND(S8*Assumptions!$B$2,2) -> 37.8 | U8: =S8+T8 -> 667.8 | V8: 31.69 | W8: =U8+V8 -> 699.49 | X8: Delivered | Y8: Reorder of prior PO
A9: Midwest | B9: Kentucky | C9: Louisville | D9: Anchor Outfitters | E9: 41026 | F9: 46153 | G9: 46162 | H9: =IF(G9="","",G9-F9) -> 9 | I9: M. Okafor | J9: Distributor | K9: Power Tools | L9: Angle Grinder 4-1/2 in | M9: PT-4500 | N9: 8 | O9: 64.5 | P9: =N9*O9 -> 516 | Q9: 0.15 | R9: =ROUND(P9*Q9,2) -> 77.4 | S9: =P9-R9 -> 438.6 | T9: =ROUND(S9*Assumptions!$B$2,2) -> 26.32 | U9: =S9+T9 -> 464.92 | V9: 39.79 | W9: =U9+V9 -> 504.71 | X9: Delivered | Y9: Damaged in transit; replaced
A10: Midwest | B10: Kentucky | C10: Louisville | D10: Anchor Outfitters | E10: 41027 | F10: 46235 | H10: =IF(G10="","",G10-F10) | I10: A. Reyes | J10: Distributor | K10: Hand Tools | L10: Adjustable Wrench 10 in | M10: HT-1000 | N10: 2 | O10: 19.5 | P10: =N10*O10 -> 39 | Q10: 0.1 | R10: =ROUND(P10*Q10,2) -> 3.9 | S10: =P10-R10 -> 35.1 | T10: =ROUND(S10*Assumptions!$B$2,2) -> 2.11 | U10: =S10+T10 -> 37.21 | V10: 9.02 | W10: =U10+V10 -> 46.23 | X10: Backordered
A11: Midwest | B11: Kentucky | C11: Louisville | D11: Anchor Outfitters | E11: 41032 | F11: 46024 | G11: 46030 | H11: =IF(G11="","",G11-F11) -> 6 | I11: M. Okafor | J11: Distributor | K11: Hand Tools | L11: Adjustable Wrench 10 in | M11: HT-1000 | N11: 10 | O11: 19.5 | P11: =N11*O11 -> 195 | Q11: 0 | R11: =ROUND(P11*Q11,2) -> 0 | S11: =P11-R11 -> 195 | T11: =ROUND(S11*Assumptions!$B$2,2) -> 11.7 | U11: =S11+T11 -> 206.7 | V11: 5.33 | W11: =U11+V11 -> 212.03 | X11: Delivered | Y11: Customer pickup
A12: Midwest | B12: Kentucky | C12: Louisville | D12: Anchor Outfitters | E12: 41033 | F12: 46202 | H12: =IF(G12="","",G12-F12) | I12: M. Okafor | J12: Distributor | K12: Hand Tools | L12: Torpedo Level 9 in | M12: HT-0900 | N12: 4 | O12: 14.25 | P12: =N12*O12 -> 57 | Q12: 0 | R12: =ROUND(P12*Q12,2) -> 0 | S12: =P12-R12 -> 57 | T12: =ROUND(S12*Assumptions!$B$2,2) -> 3.42 | U12: =S12+T12 -> 60.42 | V12: 0 | W12: =U12+V12 -> 60.42 | X12: Open | Y12: New account
A13: Midwest | B13: Kentucky | C13: Lexington | D13: Beacon Industrial | E13: 41035 | F13: 46254 | G13: 46259 | H13: =IF(G13="","",G13-F13) -> 5 | I13: A. Reyes | J13: Distributor | K13: Fasteners | L13: Lag Screw 3/8 x 4 (50) | M13: FAS-3804 | N13: 20 | O13: 22.75 | P13: =N13*O13 -> 455 | Q13: 0.15 | R13: =ROUND(P13*Q13,2) -> 68.25 | S13: =P13-R13 -> 386.75 | T13: =ROUND(S13*Assumptions!$B$2,2) -> 23.21 | U13: =S13+T13 -> 409.96 | V13: 22.32 | W13: =U13+V13 -> 432.28 | X13: Delivered | Y13: Rush order
A14: Midwest | B14: Kentucky | C14: Lexington | D14: Beacon Industrial | E14: 41038 | F14: 46037 | H14: =IF(G14="","",G14-F14) | I14: M. Okafor | J14: Online | K14: Power Tools | L14: Angle Grinder 4-1/2 in | M14: PT-4500 | N14: 40 | O14: 64.5 | P14: =N14*O14 -> 2580 | Q14: 0 | R14: =ROUND(P14*Q14,2) -> 0 | S14: =P14-R14 -> 2580 | T14: =ROUND(S14*Assumptions!$B$2,2) -> 154.8 | U14: =S14+T14 -> 2734.8 | V14: 0 | W14: =U14+V14 -> 2734.8 | X14: Open | Y14: New account
A15: Midwest | B15: Kentucky | C15: Lexington | D15: Beacon Industrial | E15: 41041 | F15: 46237 | G15: 46239 | H15: =IF(G15="","",G15-F15) -> 2 | I15: M. Okafor | J15: Online | K15: Electrical | L15: Romex 12/2 NM-B 250 ft | M15: EL-1225 | N15: 5 | O15: 118 | P15: =N15*O15 -> 590 | Q15: 0 | R15: =ROUND(P15*Q15,2) -> 0 | S15: =P15-R15 -> 590 | T15: =ROUND(S15*Assumptions!$B$2,2) -> 35.4 | U15: =S15+T15 -> 625.4 | V15: 22.86 | W15: =U15+V15 -> 648.26 | X15: Delivered
A16: Midwest | B16: Kentucky | C16: Lexington | D16: Beacon Industrial | E16: 41047 | F16: 46118 | G16: 46120 | H16: =IF(G16="","",G16-F16) -> 2 | I16: M. Okafor | J16: Online | K16: Electrical | L16: LED Shop Light 4 ft | M16: EL-0400 | N16: 24 | O16: 42 | P16: =N16*O16 -> 1008 | Q16: 0.1 | R16: =ROUND(P16*Q16,2) -> 100.8 | S16: =P16-R16 -> 907.2 | T16: =ROUND(S16*Assumptions!$B$2,2) -> 54.43 | U16: =S16+T16 -> 961.63 | V16: 11.44 | W16: =U16+V16 -> 973.07 | X16: Delivered
A17: Midwest | B17: Kentucky | C17: Lexington | D17: Beacon Industrial | E17: 41050 | F17: 46178 | G17: 46183 | H17: =IF(G17="","",G17-F17) -> 5 | I17: M. Okafor | J17: Distributor | K17: Electrical | L17: LED Shop Light 4 ft | M17: EL-0400 | N17: 30 | O17: 42 | P17: =N17*O17 -> 1260 | Q17: 0.05 | R17: =ROUND(P17*Q17,2) -> 63 | S17: =P17-R17 -> 1197 | T17: =ROUND(S17*Assumptions!$B$2,2) -> 71.82 | U17: =S17+T17 -> 1268.82 | V17: 17.31 | W17: =U17+V17 -> 1286.13 | X17: Delivered
A18: Midwest | B18: Kentucky | C18: Lexington | D18: Beacon Industrial | E18: 41054 | F18: 46131 | G18: 46140 | H18: =IF(G18="","",G18-F18) -> 9 | I18: A. Reyes | J18: Distributor | K18: Electrical | L18: LED Shop Light 4 ft | M18: EL-0400 | N18: 8 | O18: 42 | P18: =N18*O18 -> 336 | Q18: 0.1 | R18: =ROUND(P18*Q18,2) -> 33.6 | S18: =P18-R18 -> 302.4 | T18: =ROUND(S18*Assumptions!$B$2,2) -> 18.14 | U18: =S18+T18 -> 320.54 | V18: 33.7 | W18: =U18+V18 -> 354.24 | X18: Delivered
A19: Midwest | B19: Kentucky | C19: Lexington | D19: Oak Outfitters | E19: 41057 | F19: 46198 | G19: 46200 | H19: =IF(G19="","",G19-F19) -> 2 | I19: A. Reyes | J19: Direct | K19: Electrical | L19: Duplex Outlet 15A (10) | M19: EL-1510 | N19: 50 | O19: 13.4 | P19: =N19*O19 -> 670 | Q19: 0 | R19: =ROUND(P19*Q19,2) -> 0 | S19: =P19-R19 -> 670 | T19: =ROUND(S19*Assumptions!$B$2,2) -> 40.2 | U19: =S19+T19 -> 710.2 | V19: 14.1 | W19: =U19+V19 -> 724.3 | X19: Delivered | Y19: Reorder of prior PO
A20: Midwest | B20: Kentucky | C20: Lexington | D20: Oak Outfitters | E20: 41062 | F20: 46062 | G20: 46070 | H20: =IF(G20="","",G20-F20) -> 8 | I20: A. Reyes | J20: Online | K20: Hand Tools | L20: Framing Hammer 22 oz | M20: HT-2200 | N20: 25 | O20: 34.99 | P20: =N20*O20 -> 874.75 | Q20: 0.15 | R20: =ROUND(P20*Q20,2) -> 131.21 | S20: =P20-R20 -> 743.54 | T20: =ROUND(S20*Assumptions!$B$2,2) -> 44.61 | U20: =S20+T20 -> 788.15 | V20: 39.64 | W20: =U20+V20 -> 827.79 | X20: Shipped
A21: Midwest | B21: Kentucky | C21: Lexington | D21: Oak Outfitters | E21: 41063 | F21: 46189 | H21: =IF(G21="","",G21-F21) | I21: A. Reyes | J21: Direct | K21: Hand Tools | L21: Torpedo Level 9 in | M21: HT-0900 | N21: 6 | O21: 14.25 | P21: =N21*O21 -> 85.5 | Q21: 0.15 | R21: =ROUND(P21*Q21,2) -> 12.83 | S21: =P21-R21 -> 72.67 | T21: =ROUND(S21*Assumptions!$B$2,2) -> 4.36 | U21: =S21+T21 -> 77.03 | V21: 11.61 | W21: =U21+V21 -> 88.64 | X21: Backordered | Y21: New account
A22: Midwest | B22: Kentucky | C22: Lexington | D22: Oak Outfitters | E22: 41064 | F22: 46259 | G22: 46262 | H22: =IF(G22="","",G22-F22) -> 3 | I22: M. Okafor | J22: Direct | K22: Hand Tools | L22: Framing Hammer 22 oz | M22: HT-2200 | N22: 5 | O22: 34.99 | P22: =N22*O22 -> 174.95 | Q22: 0 | R22: =ROUND(P22*Q22,2) -> 0 | S22: =P22-R22 -> 174.95 | T22: =ROUND(S22*Assumptions!$B$2,2) -> 10.5 | U22: =S22+T22 -> 185.45 | V22: 15.99 | W22: =U22+V22 -> 201.44 | X22: Delivered | Y22: Partial shipment
A23: Midwest | B23: Kentucky | C23: Lexington | D23: Beacon Distributors | E23: 41069 | F23: 46230 | G23: 46233 | H23: =IF(G23="","",G23-F23) -> 3 | I23: M. Okafor | J23: Distributor | K23: Power Tools | L23: Cordless Drill 20V Kit | M23: PT-2001 | N23: 24 | O23: 129 | P23: =N23*O23 -> 3096 | Q23: 0.05 | R23: =ROUND(P23*Q23,2) -> 154.8 | S23: =P23-R23 -> 2941.2 | T23: =ROUND(S23*Assumptions!$B$2,2) -> 176.47 | U23: =S23+T23 -> 3117.67 | V23: 0.59 | W23: =U23+V23 -> 3118.26 | X23: Delivered
A24: Midwest | B24: Kentucky | C24: Lexington | D24: Beacon Distributors | E24: 41073 | F24: 46128 | G24: 46132 | H24: =IF(G24="","",G24-F24) -> 4 | I24: A. Reyes | J24: Direct | K24: Fasteners | L24: Hex Bolt 1/2 x 2, Zinc (100) | M24: FAS-1020 | N24: 15 | O24: 18.4 | P24: =N24*O24 -> 276 | Q24: 0.1 | R24: =ROUND(P24*Q24,2) -> 27.6 | S24: =P24-R24 -> 248.4 | T24: =ROUND(S24*Assumptions!$B$2,2) -> 14.9 | U24: =S24+T24 -> 263.3 | V24: 20.86 | W24: =U24+V24 -> 284.16 | X24: Shipped
A25: Midwest | B25: Kentucky | C25: Lexington | D25: Beacon Distributors | E25: 41078 | F25: 46160 | H25: =IF(G25="","",G25-F25) | I25: A. Reyes | J25: Distributor | K25: Hand Tools | L25: Torpedo Level 9 in | M25: HT-0900 | N25: 15 | O25: 14.25 | P25: =N25*O25 -> 213.75 | Q25: 0 | R25: =ROUND(P25*Q25,2) -> 0 | S25: =P25-R25 -> 213.75 | T25: =ROUND(S25*Assumptions!$B$2,2) -> 12.83 | U25: =S25+T25 -> 226.58 | V25: 19.31 | W25: =U25+V25 -> 245.89 | X25: Backordered | Y25: Partial shipment
A26: Midwest | B26: Ohio | C26: Cincinnati | D26: Ridge Fabrication | E26: 41085 | F26: 46220 | H26: =IF(G26="","",G26-F26) | I26: A. Reyes | J26: Online | K26: Electrical | L26: LED Shop Light 4 ft | M26: EL-0400 | N26: 20 | O26: 42 | P26: =N26*O26 -> 840 | Q26: 0.15 | R26: =ROUND(P26*Q26,2) -> 126 | S26: =P26-R26 -> 714 | T26: =ROUND(S26*Assumptions!$B$2,2) -> 42.84 | U26: =S26+T26 -> 756.84 | V26: 0 | W26: =U26+V26 -> 756.84 | X26: Open
A27: Midwest | B27: Ohio | C27: Cincinnati | D27: Ridge Fabrication | E27: 41088 | F27: 46099 | H27: =IF(G27="","",G27-F27) | I27: A. Reyes | J27: Direct | K27: Power Tools | L27: Circular Saw 7-1/4 in | M27: PT-7250 | N27: 50 | O27: 99 | P27: =N27*O27 -> 4950 | Q27: 0 | R27: =ROUND(P27*Q27,2) -> 0 | S27: =P27-R27 -> 4950 | T27: =ROUND(S27*Assumptions!$B$2,2) -> 297 | U27: =S27+T27 -> 5247 | V27: 0 | W27: =U27+V27 -> 5247 | X27: Open
A28: Midwest | B28: Ohio | C28: Cincinnati | D28: Ridge Fabrication | E28: 41093 | F28: 46100 | H28: =IF(G28="","",G28-F28) | I28: A. Reyes | J28: Online | K28: Hand Tools | L28: Adjustable Wrench 10 in | M28: HT-1000 | N28: 50 | O28: 19.5 | P28: =N28*O28 -> 975 | Q28: 0 | R28: =ROUND(P28*Q28,2) -> 0 | S28: =P28-R28 -> 975 | T28: =ROUND(S28*Assumptions!$B$2,2) -> 58.5 | U28: =S28+T28 -> 1033.5 | V28: 0 | W28: =U28+V28 -> 1033.5 | X28: Open | Y28: Customer pickup
A29: Midwest | B29: Ohio | C29: Cincinnati | D29: Ridge Fabrication | E29: 41098 | F29: 46032 | G29: 46036 | H29: =IF(G29="","",G29-F29) -> 4 | I29: M. Okafor | J29: Online | K29: Hand Tools | L29: Adjustable Wrench 10 in | M29: HT-1000 | N29: 8 | O29: 19.5 | P29: =N29*O29 -> 156 | Q29: 0.05 | R29: =ROUND(P29*Q29,2) -> 7.8 | S29: =P29-R29 -> 148.2 | T29: =ROUND(S29*Assumptions!$B$2,2) -> 8.89 | U29: =S29+T29 -> 157.09 | V29: 43.29 | W29: =U29+V29 -> 200.38 | X29: Delivered | Y29: Net 30 terms
A30: Midwest | B30: Ohio | C30: Cincinnati | D30: Riverside Distributors | E30: 41099 | F30: 46162 | G30: 46170 | H30: =IF(G30="","",G30-F30) -> 8 | I30: M. Okafor | J30: Online | K30: Power Tools | L30: Angle Grinder 4-1/2 in | M30: PT-4500 | N30: 3 | O30: 64.5 | P30: =N30*O30 -> 193.5 | Q30: 0.15 | R30: =ROUND(P30*Q30,2) -> 29.03 | S30: =P30-R30 -> 164.47 | T30: =ROUND(S30*Assumptions!$B$2,2) -> 9.87 | U30: =S30+T30 -> 174.34 | V30: 25.53 | W30: =U30+V30 -> 199.87 | X30: Shipped | Y30: Reorder of prior PO
A31: Midwest | B31: Ohio | C31: Cincinnati | D31: Riverside Distributors | E31: 41101 | F31: 46129 | G31: 46131 | H31: =IF(G31="","",G31-F31) -> 2 | I31: A. Reyes | J31: Online | K31: Fasteners | L31: Lag Screw 3/8 x 4 (50) | M31: FAS-3804 | N31: 12 | O31: 22.75 | P31: =N31*O31 -> 273 | Q31: 0 | R31: =ROUND(P31*Q31,2) -> 0 | S31: =P31-R31 -> 273 | T31: =ROUND(S31*Assumptions!$B$2,2) -> 16.38 | U31: =S31+T31 -> 289.38 | V31: 15.95 | W31: =U31+V31 -> 305.33 | X31: Delivered
A32: Midwest | B32: Ohio | C32: Cincinnati | D32: Riverside Distributors | E32: 41105 | F32: 46208 | G32: 46215 | H32: =IF(G32="","",G32-F32) -> 7 | I32: A. Reyes | J32: Online | K32: Electrical | L32: LED Shop Light 4 ft | M32: EL-0400 | N32: 24 | O32: 42 | P32: =N32*O32 -> 1008 | Q32: 0 | R32: =ROUND(P32*Q32,2) -> 0 | S32: =P32-R32 -> 1008 | T32: =ROUND(S32*Assumptions!$B$2,2) -> 60.48 | U32: =S32+T32 -> 1068.48 | V32: 1.03 | W32: =U32+V32 -> 1069.51 | X32: Delivered | Y32: New account
A33: Midwest | B33: Ohio | C33: Cincinnati | D33: Riverside Distributors | E33: 41112 | F33: 46210 | H33: =IF(G33="","",G33-F33) | I33: A. Reyes | J33: Direct | K33: Power Tools | L33: Angle Grinder 4-1/2 in | M33: PT-4500 | N33: 12 | O33: 64.5 | P33: =N33*O33 -> 774 | Q33: 0.05 | R33: =ROUND(P33*Q33,2) -> 38.7 | S33: =P33-R33 -> 735.3 | T33: =ROUND(S33*Assumptions!$B$2,2) -> 44.12 | U33: =S33+T33 -> 779.42 | V33: 40.94 | W33: =U33+V33 -> 820.36 | X33: Backordered
A34: Midwest | B34: Ohio | C34: Cincinnati | D34: Riverside Distributors | E34: 41115 | F34: 46261 | G34: 46263 | H34: =IF(G34="","",G34-F34) -> 2 | I34: M. Okafor | J34: Direct | K34: Fasteners | L34: Lag Screw 3/8 x 4 (50) | M34: FAS-3804 | N34: 24 | O34: 22.75 | P34: =N34*O34 -> 546 | Q34: 0 | R34: =ROUND(P34*Q34,2) -> 0 | S34: =P34-R34 -> 546 | T34: =ROUND(S34*Assumptions!$B$2,2) -> 32.76 | U34: =S34+T34 -> 578.76 | V34: 42.07 | W34: =U34+V34 -> 620.83 | X34: Delivered | Y34: Net 30 terms
A35: Midwest | B35: Ohio | C35: Cincinnati | D35: Riverside Distributors | E35: 41122 | F35: 46118 | G35: 46120 | H35: =IF(G35="","",G35-F35) -> 2 | I35: M. Okafor | J35: Online | K35: Safety | L35: Hard Hat, Type I | M35: SF-0001 | N35: 12 | O35: 21.95 | P35: =N35*O35 -> 263.4 | Q35: 0.05 | R35: =ROUND(P35*Q35,2) -> 13.17 | S35: =P35-R35 -> 250.23 | T35: =ROUND(S35*Assumptions!$B$2,2) -> 15.01 | U35: =S35+T35 -> 265.24 | V35: 34.42 | W35: =U35+V35 -> 299.66 | X35: Delivered | Y35: Partial shipment
A36: Midwest | B36: Ohio | C36: Cincinnati | D36: Cedar Farm & Feed | E36: 41123 | F36: 46037 | G36: 46041 | H36: =IF(G36="","",G36-F36) -> 4 | I36: M. Okafor | J36: Online | K36: Fasteners | L36: Deck Screw #10 x 3 (5 lb) | M36: FAS-1003 | N36: 25 | O36: 31.9 | P36: =N36*O36 -> 797.5 | Q36: 0 | R36: =ROUND(P36*Q36,2) -> 0 | S36: =P36-R36 -> 797.5 | T36: =ROUND(S36*Assumptions!$B$2,2) -> 47.85 | U36: =S36+T36 -> 845.35 | V36: 9.93 | W36: =U36+V36 -> 855.28 | X36: Delivered
A37: Midwest | B37: Ohio | C37: Cincinnati | D37: Cedar Farm & Feed | E37: 41128 | F37: 46211 | G37: 46213 | H37: =IF(G37="","",G37-F37) -> 2 | I37: A. Reyes | J37: Online | K37: Fasteners | L37: Deck Screw #10 x 3 (5 lb) | M37: FAS-1003 | N37: 6 | O37: 31.9 | P37: =N37*O37 -> 191.4 | Q37: 0.15 | R37: =ROUND(P37*Q37,2) -> 28.71 | S37: =P37-R37 -> 162.69 | T37: =ROUND(S37*Assumptions!$B$2,2) -> 9.76 | U37: =S37+T37 -> 172.45 | V37: 12.68 | W37: =U37+V37 -> 185.13 | X37: Delivered | Y37: New account
A38: Midwest | B38: Ohio | C38: Cincinnati | D38: Cedar Farm & Feed | E38: 41130 | F38: 46056 | G38: 46061 | H38: =IF(G38="","",G38-F38) -> 5 | I38: M. Okafor | J38: Distributor | K38: Electrical | L38: LED Shop Light 4 ft | M38: EL-0400 | N38: 30 | O38: 42 | P38: =N38*O38 -> 1260 | Q38: 0 | R38: =ROUND(P38*Q38,2) -> 0 | S38: =P38-R38 -> 1260 | T38: =ROUND(S38*Assumptions!$B$2,2) -> 75.6 | U38: =S38+T38 -> 1335.6 | V38: 17.68 | W38: =U38+V38 -> 1353.28 | X38: Shipped | Y38: Net 30 terms
A39: Midwest | B39: Ohio | C39: Columbus | D39: Maple Farm & Feed | E39: 41137 | F39: 46253 | H39: =IF(G39="","",G39-F39) | I39: M. Okafor | J39: Direct | K39: Electrical | L39: Duplex Outlet 15A (10) | M39: EL-1510 | N39: 3 | O39: 13.4 | P39: =N39*O39 -> 40.2 | Q39: 0.15 | R39: =ROUND(P39*Q39,2) -> 6.03 | S39: =P39-R39 -> 34.17 | T39: =ROUND(S39*Assumptions!$B$2,2) -> 2.05 | U39: =S39+T39 -> 36.22 | V39: 0 | W39: =U39+V39 -> 36.22 | X39: Open | Y39: Net 30 terms
A40: Midwest | B40: Ohio | C40: Columbus | D40: Maple Farm & Feed | E40: 41138 | F40: 46063 | G40: 46070 | H40: =IF(G40="","",G40-F40) -> 7 | I40: M. Okafor | J40: Direct | K40: Fasteners | L40: Deck Screw #10 x 3 (5 lb) | M40: FAS-1003 | N40: 30 | O40: 31.9 | P40: =N40*O40 -> 957 | Q40: 0 | R40: =ROUND(P40*Q40,2) -> 0 | S40: =P40-R40 -> 957 | T40: =ROUND(S40*Assumptions!$B$2,2) -> 57.42 | U40: =S40+T40 -> 1014.42 | V40: 15.02 | W40: =U40+V40 -> 1029.44 | X40: Delivered | Y40: Customer pickup
...

Sheet Assumptions
A1: Assumption | B1: Value
A2: Sales tax rate | B2: 0.06
A3: Data is fictional and generated for documentation screenshots.
